Workbook

Sheet DATOS
B2: EMPRENDIMIENTO E INNOVACIÓN EMPRESARIAL
B3: CARRERA
B4: GRUPO
B5: IDEA DE NEGOCIO
B6: LOCALIDAD

Sheet Gastos
B1: =+DATOS!C5 -> 0
B3: GASTOS INICIALES | C3: Gastos de Inicio | D3: Presupuesto Mensual
B5: Gastos Generales de Inicio
B7: Permisos Municipales
B8: Gastos de Constitución
B9: Muebles de Oficina
B10: Pago de Prestamos Anteriores
B11: Computador
B12: Software (general)
B13: Compra de Materias Primas o Mercadería | D13: 0
B14: Total | C14: =SUM(C7:C13) -> 0 | D14: =SUM(D7:D13) -> 0
B15: Gastos Administrativos
B17: Sueldos y Salrarios
B18: Pagos Iess | D18: =+D17*12.15% -> 0
B19: Pagos Sri | D19: 0
B20: Honorarios Profesionales
B21: Capacitaciones
B22: Transportes de Mercadería
B23: Cánones /Arrendamiento
B24: Primas de Seguros
B25: Suministros varios
B26: Otros
B27: Total | C27: =SUM(C17:C26) -> 0 | D27: =SUM(D17:D26) -> 0
B28: Gastos Marketing y Ventas
B30: Publicidad
B31: Desarrollo de Marca / Identidad
B32: Sitio web
B33: Material de marketing impreso
B34: Tarifas de anuncios
B35: Mercadeo por Internet
B36: Ferias de muestras
B37: Otros
B38: Total | C38: =SUM(C30:C37) -> 0 | D38: =SUM(D30:D37) -> 0
B39: Gastos Financieros
B41: Intereses Bancarios
B42: Comisiones Bancarias
B43: Maquinas para Tarjeta de Crédito
B44: Cheques / Estado de Cuenta
B45: Total | C45: =SUM(C41:C44) -> 0 | D45: =SUM(D41:D44) -> 0
B46: Otros
...

Sheet Información general de Startup
B1: =+DATOS!C5 -> 0
B2: INFORMACIÓN GENERAL DE STARTUP | D2: Presupuesto Mensual | E2: Presupuesto Acumulado en meses
E3: 3
C5: Gastos totales | D5: =SUM(D7:D11) -> 0 | E5: =SUM(E7:E11) -> 0
C7: =+Gastos!B5 -> Gastos Generales de Inicio | D7: =+Gastos!D14+Gastos!C14 -> 0 | E7: =Gastos!D14*$E$3 -> 0
C8: =+Gastos!B15 -> Gastos Administrativos | D8: =+Gastos!D27+Gastos!C27 -> 0 | E8: =+Gastos!D27*E3 -> 0
C9: =+Gastos!B28 -> Gastos Marketing y Ventas | D9: =+Gastos!D38+Gastos!C38 -> 0 | E9: =+Gastos!D38*E3 -> 0
C10: =+Gastos!B39 -> Gastos Financieros | D10: =+Gastos!D45+Gastos!C45 -> 0 | E10: =+Gastos!D45*E3 -> 0
C11: =+Gastos!B46 -> Otros | D11: =+Gastos!D53+Gastos!C53 -> 0 | E11: =+Gastos!D53*E3 -> 0
C13: Financiación Sugerida | D13: =+D5+E5 -> 0
C15: Inversores
C16: Préstamos
C17: Financiación adicional
C19: Financiamiento | D19: =+D5+E5-D15 -> 0
B21: FINANCIAMIENTO DE INICIO | D21: Presupuesto
C23: Inversores
C25: Propietario 1
C26: Propietario 2
C27: Propietario 3
C28: Otros
C29: Total | D29: =SUM(D25:D28) -> 0
C30: Préstamos
C33: Préstamo bancario | D33: =+(D5+E5)-D29 -> 0
C34: Préstamo no bancario
C35: Otros | D35: 0
C36: Total | D36: =SUM(D33:D35) -> 0
C37: Financiación adicional
C39: concesión
C40: Otros
C41: Total | D41: =SUM(D39:D40) -> 0
C43: Financiación total para la puesta en marcha | D43: =+D19 -> 0

Sheet Beneficios y pérdidas
B3: =+DATOS!C5 -> 0
B5: INGRESOS | C5: =DATE(YEAR(TODAY()),1,1) -> 45658 | D5: =DATE(YEAR(C5),MONTH(C5)+1,1) -> 45689 | E5: =DATE(YEAR(D5),MONTH(D5)+1,1) -> 45717 | F5: =DATE(YEAR(E5),MONTH(E5)+1,1) -> 45748 | G5: =DATE(YEAR(F5),MONTH(F5)+1,1) -> 45778 | H5: =DATE(YEAR(G5),MONTH(G5)+1,1) -> 45809 | I5: =DATE(YEAR(H5),MONTH(H5)+1,1) -> 45839 | J5: =DATE(YEAR(I5),MONTH(I5)+1,1) -> 45870 | K5: =DATE(YEAR(J5),MONTH(J5)+1,1) -> 45901 | ... N5: =DATE(YEAR(M5),MONTH(M5)+1,1) -> 45992 | O5: AÑO HASTA LA FECHA
B6: UNIDADES
B7: PVP
B8: Ventas estimadas | C8: =+C6*C7 -> 0 | D8: =+D6*D7 -> 0 | E8: =+E6*E7 -> 0 | F8: =+F6*F7 -> 0 | G8: =+G6*G7 -> 0 | H8: =+H6*H7 -> 0 | I8: =+I6*I7 -> 0 | J8: =+J6*J7 -> 0 | ... N8: =+N6*N7 -> 0 | O8: =SUM(C8:N8) -> 0
B9: Menos (descuentos, errores, etc.) | C9: =+C8*0.1 -> 0 | D9: =+D8*0.1 -> 0 | E9: =+E8*0.1 -> 0 | F9: =+F8*0.1 -> 0 | G9: =+G8*0.1 -> 0 | H9: =+H8*0.1 -> 0 | I9: =+I8*0.1 -> 0 | J9: =+J8*0.1 -> 0 | ... N9: =+N8*0.1 -> 0 | O9: =SUM(C9:N9) -> 0
B10: Ingresos por servicios | C10: 0 | D10: 0 | E10: 0 | F10: 0 | G10: 0 | H10: 0 | I10: 0 | J10: 0 | K10: 0 | L10: 0 | M10: 0 | N10: 0 | O10: =SUM(C10:N10) -> 0
B11: Otros ingresos | C11: 0 | D11: 0 | E11: 0 | F11: 0 | G11: 0 | H11: 0 | I11: 0 | J11: 0 | K11: 0 | L11: 0 | M11: 0 | N11: 0 | O11: =SUM(C11:N11) -> 0
B12: Ventas netas | C12: =SUM(C8:C11) -> 0 | D12: =SUM(D8:D11) -> 0 | E12: =SUM(E8:E11) -> 0 | F12: =SUM(F8:F11) -> 0 | G12: =SUM(G8:G11) -> 0 | H12: =SUM(H8:H11) -> 0 | I12: =SUM(I8:I11) -> 0 | J12: =SUM(J8:J11) -> 0 | ... N12: =SUM(N8:N11) -> 0 | O12: =SUM(C12:N12) -> 0
B13: Coste de bienes vendidos | O13: =SUM(C13:N13) -> 0
B14: Beneficio bruto | C14: =C12-C13 -> 0 | D14: =D12-D13 -> 0 | E14: =E12-E13 -> 0 | F14: =F12-F13 -> 0 | G14: =G12-G13 -> 0 | H14: =H12-H13 -> 0 | I14: =I12-I13 -> 0 | J14: =J12-J13 -> 0 | ... N14: =N12-N13 -> 0 | O14: =SUM(C14:N14) -> 0
B16: GASTOS | C16: =C5 -> 45658 | D16: =DATE(YEAR(C16),MONTH(C16)+1,1) -> 45689 | E16: =DATE(YEAR(D16),MONTH(D16)+1,1) -> 45717 | F16: =DATE(YEAR(E16),MONTH(E16)+1,1) -> 45748 | G16: =DATE(YEAR(F16),MONTH(F16)+1,1) -> 45778 | H16: =DATE(YEAR(G16),MONTH(G16)+1,1) -> 45809 | I16: =DATE(YEAR(H16),MONTH(H16)+1,1) -> 45839 | J16: =DATE(YEAR(I16),MONTH(I16)+1,1) -> 45870 | K16: =DATE(YEAR(J16),MONTH(J16)+1,1) -> 45901 | ... N16: =DATE(YEAR(M16),MONTH(M16)+1,1) -> 45992 | O16: AÑO HASTA LA FECHA
B17: =+'Información general de Startup'!C7 -> Gastos Generales de Inicio | C17: =+Gastos!D14+Gastos!C14 -> 0 | D17: =+Gastos!D14 -> 0 | E17: =+D17 -> 0 | F17: =+E17 -> 0 | G17: =+F17 -> 0 | H17: =+G17 -> 0 | I17: =+H17 -> 0 | J17: =+I17 -> 0 | K17: =+J17 -> 0 | L17: =+K17 -> 0 | ... N17: =+M17 -> 0 | O17: =SUM(C17:N17) -> 0
B18: =+Gastos!B15 -> Gastos Administrativos | C18: =+Gastos!D27+Gastos!C27 -> 0 | D18: =+Gastos!D27 -> 0 | E18: =+D18 -> 0 | F18: =+E18 -> 0 | G18: =+F18 -> 0 | H18: =+G18 -> 0 | I18: =+H18 -> 0 | J18: =+I18 -> 0 | K18: =+J18 -> 0 | L18: =+K18 -> 0 | ... N18: =+M18 -> 0 | O18: =SUM(C18:N18) -> 0
B19: =+Gastos!B28 -> Gastos Marketing y Ventas | C19: =+Gastos!D38+Gastos!C38 -> 0 | D19: =+Gastos!D38 -> 0 | E19: =+D19 -> 0 | F19: =+E19 -> 0 | G19: =+F19 -> 0 | H19: =+G19 -> 0 | I19: =+H19 -> 0 | J19: =+I19 -> 0 | K19: =+J19 -> 0 | L19: =+K19 -> 0 | ... N19: =+M19 -> 0 | O19: =SUM(C19:N19) -> 0
B20: =+Gastos!B39 -> Gastos Financieros | C20: =+Gastos!D45+Gastos!C45 -> 0 | D20: =+Gastos!D45 -> 0 | E20: =+D20 -> 0 | F20: =+E20 -> 0 | G20: =+F20 -> 0 | H20: =+G20 -> 0 | I20: =+H20 -> 0 | J20: =+I20 -> 0 | K20: =+J20 -> 0 | L20: =+K20 -> 0 | ... N20: =+M20 -> 0 | O20: =SUM(C20:N20) -> 0
B21: =+Gastos!B46 -> Otros | C21: =+Gastos!D53+Gastos!C53 -> 0 | D21: =+C21 -> 0 | E21: =+D21 -> 0 | F21: =+E21 -> 0 | G21: =+F21 -> 0 | H21: =+G21 -> 0 | I21: =+H21 -> 0 | J21: =+I21 -> 0 | K21: =+J21 -> 0 | ... N21: =+M21 -> 0 | O21: =SUM(C21:N21) -> 0
B22: Gastos totales | C22: =SUM(C17:C21) -> 0 | D22: =SUM(D17:D21) -> 0 | E22: =SUM(E17:E21) -> 0 | F22: =SUM(F17:F21) -> 0 | G22: =SUM(G17:G21) -> 0 | H22: =SUM(H17:H21) -> 0 | I22: =SUM(I17:I21) -> 0 | J22: =SUM(J17:J21) -> 0 | ... N22: =SUM(N17:N21) -> 0 | O22: =SUM(C22:N22) -> 0
B23: Ingresos | C23: =C14-C22 -> 0 | D23: =D14-D22 -> 0 | E23: =E14-E22 -> 0 | F23: =F14-F22 -> 0 | G23: =G14-G22 -> 0 | H23: =H14-H22 -> 0 | I23: =I14-I22 -> 0 | J23: =J14-J22 -> 0 | ... N23: =N14-N22 -> 0 | O23: =SUM(C23:N23) -> 0
B24: Gastos de impuestos | C24: =+IF(C23>0,C23*0.25,0) -> 0 | D24: =+IF(D23>0,D23*0.25,0) -> 0 | E24: =+IF(E23>0,E23*0.25,0) -> 0 | F24: =+IF(F23>0,F23*0.25,0) -> 0 | G24: =+IF(G23>0,G23*0.25,0) -> 0 | H24: =+IF(H23>0,H23*0.25,0) -> 0 | I24: =+IF(I23>0,I23*0.25,0) -> 0 | J24: =+IF(J23>0,J23*0.25,0) -> 0 | ... N24: =+IF(N23>0,N23*0.25,0) -> 0 | O24: =SUM(C24:N24) -> 0
B26: Posición de Efectivo | C26: =C23-C24 -> 0 | D26: =D23-D24 -> 0 | E26: =E23-E24 -> 0 | F26: =F23-F24 -> 0 | G26: =G23-G24 -> 0 | H26: =H23-H24 -> 0 | I26: =I23-I24 -> 0 | J26: =J23-J24 -> 0 | ... N26: =N23-N24 -> 0 | O26: =SUM(C26:N26) -> 0
E28: MODO INCORRECTO | I28: MODO ICORRECTO
B29: ERROR NO GANO EL 30% PARA UBICAR EL PVP | E29: VENTA | F29: =+C31 -> 0 | I29: VENTA | J29: =+E33 -> 0
C30: 0.3 | E30: COSTO | G30: =+F30/F29 -> #DIV/0! | I30: COSTO | K30: =+J30/J29 -> #DIV/0!
C31: =+C29+(C29*C30) -> 0 | E31: GANANCIA | F31: =+F29-F30 -> 0 | G31: =+F31/F29 -> #DIV/0! | I31: GANANCIA | J31: =+J29-J30 -> 0 | K31: =+J31/J29 -> #DIV/0!
C33: COSTO | E33: =+C29/(1-C30) -> 0
C34: 1-% RENTABILIDAD

Sheet amort
B1: CUADRO DE AMORTIZACIÓN DE UN PRÉSTAMO
A2: Introducción de datos:
A3: Capital inicial: | B3: =+'Información general de Startup'!D43 -> 0
A4: Tipo de interés nominal: | B4: 0.15
A5: Plazo Años: | B5: 3
A6: Periodicidad en meses: | B6: 12
B7: Comisión de apertura: | C7: 0 | E7: Capital efectivo: | F7: =B3-F5-F6-C9-C10 -> 0
B8: Comisión de gestión: | C8: 0 | E8: T.A.E. real | F8: =EFFECT(RATE(B5*B6,PMT(B4/B6,B5*B6,B3,,C12),F7,,C12,0.1)*B6,B6) -> #NUM!
B9: Gastos fijos bancarios: | C9: 0
B10: Gastos adicionales: | C10: 0
B11: Comisión de cancelación anticipada | C11: 0
B12: Prepagable (1) o pospagable (0) | C12: 0
B14: Resultados:
B16: Periodos de pago | C16: Cuota | D16: Pago de intereses | E16: Amortización del principal | F16: Amortización acumulada del principal | G16: Capital pendiente | H16: Importe de la comisión de cancelación | I16: Coste de cancelación
B17: 0 | G17: =B3 -> 0
B18: =IF(B17<$B$5*$B$6,B17+1,"") -> 1 | C18: =IF(B18="","",-PMT($B$4/$B$6,$B$5*$B$6,$B$3,,$C$12)) -> 0 | D18: =IF(B18="","",$B$4/$B$6*G17) -> 0 | E18: =IF(B18="","",C18-D18) -> 0 | F18: =IF(B18="","",E18+F17) -> 0 | G18: =IF(B18="","",$G$17-F18) -> 0 | H18: =IF(B18="","",$C$11*G18) -> 0 | I18: =IF(B18="","",G18+H18) -> 0
B19: =IF(B18<$B$5*$B$6,B18+1,"") -> 2 | C19: =IF(B19="","",-PMT($B$4/$B$6,$B$5*$B$6,$B$3,,$C$12)) -> 0 | D19: =IF(B19="","",$B$4/$B$6*G18) -> 0 | E19: =IF(B19="","",C19-D19) -> 0 | F19: =IF(B19="","",E19+F18) -> 0 | G19: =IF(B19="","",$G$17-F19) -> 0 | H19: =IF(B19="","",$C$11*G19) -> 0 | I19: =IF(B19="","",G19+H19) -> 0
B20: =IF(B19<$B$5*$B$6,B19+1,"") -> 3 | C20: =IF(B20="","",-PMT($B$4/$B$6,$B$5*$B$6,$B$3,,$C$12)) -> 0 | D20: =IF(B20="","",$B$4/$B$6*G19) -> 0 | E20: =IF(B20="","",C20-D20) -> 0 | F20: =IF(B20="","",E20+F19) -> 0 | G20: =IF(B20="","",$G$17-F20) -> 0 | H20: =IF(B20="","",$C$11*G20) -> 0 | I20: =IF(B20="","",G20+H20) -> 0
B21: =IF(B20<$B$5*$B$6,B20+1,"") -> 4 | C21: =IF(B21="","",-PMT($B$4/$B$6,$B$5*$B$6,$B$3,,$C$12)) -> 0 | D21: =IF(B21="","",$B$4/$B$6*G20) -> 0 | E21: =IF(B21="","",C21-D21) -> 0 | F21: =IF(B21="","",E21+F20) -> 0 | G21: =IF(B21="","",$G$17-F21) -> 0 | H21: =IF(B21="","",$C$11*G21) -> 0 | I21: =IF(B21="","",G21+H21) -> 0
B22: =IF(B21<$B$5*$B$6,B21+1,"") -> 5 | C22: =IF(B22="","",-PMT($B$4/$B$6,$B$5*$B$6,$B$3,,$C$12)) -> 0 | D22: =IF(B22="","",$B$4/$B$6*G21) -> 0 | E22: =IF(B22="","",C22-D22) -> 0 | F22: =IF(B22="","",E22+F21) -> 0 | G22: =IF(B22="","",$G$17-F22) -> 0 | H22: =IF(B22="","",$C$11*G22) -> 0 | I22: =IF(B22="","",G22+H22) -> 0
B23: =IF(B22<$B$5*$B$6,B22+1,"") -> 6 | C23: =IF(B23="","",-PMT($B$4/$B$6,$B$5*$B$6,$B$3,,$C$12)) -> 0 | D23: =IF(B23="","",$B$4/$B$6*G22) -> 0 | E23: =IF(B23="","",C23-D23) -> 0 | F23: =IF(B23="","",E23+F22) -> 0 | G23: =IF(B23="","",$G$17-F23) -> 0 | H23: =IF(B23="","",$C$11*G23) -> 0 | I23: =IF(B23="","",G23+H23) -> 0
B24: =IF(B23<$B$5*$B$6,B23+1,"") -> 7 | C24: =IF(B24="","",-PMT($B$4/$B$6,$B$5*$B$6,$B$3,,$C$12)) -> 0 | D24: =IF(B24="","",$B$4/$B$6*G23) -> 0 | E24: =IF(B24="","",C24-D24) -> 0 | F24: =IF(B24="","",E24+F23) -> 0 | G24: =IF(B24="","",$G$17-F24) -> 0 | H24: =IF(B24="","",$C$11*G24) -> 0 | I24: =IF(B24="","",G24+H24) -> 0
B25: =IF(B24<$B$5*$B$6,B24+1,"") -> 8 | C25: =IF(B25="","",-PMT($B$4/$B$6,$B$5*$B$6,$B$3,,$C$12)) -> 0 | D25: =IF(B25="","",$B$4/$B$6*G24) -> 0 | E25: =IF(B25="","",C25-D25) -> 0 | F25: =IF(B25="","",E25+F24) -> 0 | G25: =IF(B25="","",$G$17-F25) -> 0 | H25: =IF(B25="","",$C$11*G25) -> 0 | I25: =IF(B25="","",G25+H25) -> 0
B26: =IF(B25<$B$5*$B$6,B25+1,"") -> 9 | C26: =IF(B26="","",-PMT($B$4/$B$6,$B$5*$B$6,$B$3,,$C$12)) -> 0 | D26: =IF(B26="","",$B$4/$B$6*G25) -> 0 | E26: =IF(B26="","",C26-D26) -> 0 | F26: =IF(B26="","",E26+F25) -> 0 | G26: =IF(B26="","",$G$17-F26) -> 0 | H26: =IF(B26="","",$C$11*G26) -> 0 | I26: =IF(B26="","",G26+H26) -> 0
B27: =IF(B26<$B$5*$B$6,B26+1,"") -> 10 | C27: =IF(B27="","",-PMT($B$4/$B$6,$B$5*$B$6,$B$3,,$C$12)) -> 0 | D27: =IF(B27="","",$B$4/$B$6*G26) -> 0 | E27: =IF(B27="","",C27-D27) -> 0 | F27: =IF(B27="","",E27+F26) -> 0 | G27: =IF(B27="","",$G$17-F27) -> 0 | H27: =IF(B27="","",$C$11*G27) -> 0 | I27: =IF(B27="","",G27+H27) -> 0
B28: =IF(B27<$B$5*$B$6,B27+1,"") -> 11 | C28: =IF(B28="","",-PMT($B$4/$B$6,$B$5*$B$6,$B$3,,$C$12)) -> 0 | D28: =IF(B28="","",$B$4/$B$6*G27) -> 0 | E28: =IF(B28="","",C28-D28) -> 0 | F28: =IF(B28="","",E28+F27) -> 0 | G28: =IF(B28="","",$G$17-F28) -> 0 | H28: =IF(B28="","",$C$11*G28) -> 0 | I28: =IF(B28="","",G28+H28) -> 0
B29: =IF(B28<$B$5*$B$6,B28+1,"") -> 12 | C29: =IF(B29="","",-PMT($B$4/$B$6,$B$5*$B$6,$B$3,,$C$12)) -> 0 | D29: =IF(B29="","",$B$4/$B$6*G28) -> 0 | E29: =IF(B29="","",C29-D29) -> 0 | F29: =IF(B29="","",E29+F28) -> 0 | G29: =IF(B29="","",$G$17-F29) -> 0 | H29: =IF(B29="","",$C$11*G29) -> 0 | I29: =IF(B29="","",G29+H29) -> 0
... B41: =IF(B40<$B$5*$B$6,B40+1,"") -> 24 | C41: =IF(B41="","",-PMT($B$4/$B$6,$B$5*$B$6,$B$3,,$C$12)) -> 0 | D41: =IF(B41="","",$B$4/$B$6*G40) -> 0 | E41: =IF(B41="","",C41-D41) -> 0 | F41: =IF(B41="","",E41+F40) -> 0 | G41: =IF(B41="","",$G$17-F41) -> 0 | H41: =IF(B41="","",$C$11*G41) -> 0 | I41: =IF(B41="","",G41+H41) -> 0
B42: =IF(B41<$B$5*$B$6,B41+1,"") -> 25 | C42: =IF(B42<=$B$5*$B$6,-PMT($B$4/$B$6,$B$5*$B$6,$B$3,,$C$12),"") -> 0 | D42: =IF(B42<=$B$5*$B$6,-IPMT($B$4/$B$6,B42,$B$5*$B$6,$B$3,,$C$12),"") -> 0 | E42: =IF(B42<=$B$5*$B$6,-PPMT($B$4/$B$6,B42,$B$5*$B$6,$B$3,,$C$12),"") -> 0 | F42: =IF(B42<=$B$5*$B$6,SUM($E$18:E42),"") -> 0 | G42: =IF(B42<=$B$5*$B$6,$B$3-F42,"") -> 0 | H42: =IF(G42="","",$C$11*G42) -> 0 | I42: =IF(H42="","",G42+H42) -> 0
B43: =IF(B42<$B$5*$B$6,B42+1,"") -> 26 | C43: =IF(B43<=$B$5*$B$6,-PMT($B$4/$B$6,$B$5*$B$6,$B$3,,$C$12),"") -> 0 | D43: =IF(B43<=$B$5*$B$6,-IPMT($B$4/$B$6,B43,$B$5*$B$6,$B$3,,$C$12),"") -> 0 | E43: =IF(B43<=$B$5*$B$6,-PPMT($B$4/$B$6,B43,$B$5*$B$6,$B$3,,$C$12),"") -> 0 | F43: =IF(B43<=$B$5*$B$6,SUM($E$18:E43),"") -> 0 | G43: =IF(B43<=$B$5*$B$6,$B$3-F43,"") -> 0 | H43: =IF(G43="","",$C$11*G43) -> 0 | I43: =IF(H43="","",G43+H43) -> 0
B44: =IF(B43<$B$5*$B$6,B43+1,"") -> 27 | C44: =IF(B44<=$B$5*$B$6,-PMT($B$4/$B$6,$B$5*$B$6,$B$3,,$C$12),"") -> 0 | D44: =IF(B44<=$B$5*$B$6,-IPMT($B$4/$B$6,B44,$B$5*$B$6,$B$3,,$C$12),"") -> 0 | E44: =IF(B44<=$B$5*$B$6,-PPMT($B$4/$B$6,B44,$B$5*$B$6,$B$3,,$C$12),"") -> 0 | F44: =IF(B44<=$B$5*$B$6,SUM($E$18:E44),"") -> 0 | G44: =IF(B44<=$B$5*$B$6,$B$3-F44,"") -> 0 | H44: =IF(G44="","",$C$11*G44) -> 0 | I44: =IF(H44="","",G44+H44) -> 0
B45: =IF(B44<$B$5*$B$6,B44+1,"") -> 28 | C45: =IF(B45<=$B$5*$B$6,-PMT($B$4/$B$6,$B$5*$B$6,$B$3,,$C$12),"") -> 0 | D45: =IF(B45<=$B$5*$B$6,-IPMT($B$4/$B$6,B45,$B$5*$B$6,$B$3,,$C$12),"") -> 0 | E45: =IF(B45<=$B$5*$B$6,-PPMT($B$4/$B$6,B45,$B$5*$B$6,$B$3,,$C$12),"") -> 0 | F45: =IF(B45<=$B$5*$B$6,SUM($E$18:E45),"") -> 0 | G45: =IF(B45<=$B$5*$B$6,$B$3-F45,"") -> 0 | H45: =IF(G45="","",$C$11*G45) -> 0 | I45: =IF(H45="","",G45+H45) -> 0
B46: =IF(B45<$B$5*$B$6,B45+1,"") -> 29 | C46: =IF(B46<=$B$5*$B$6,-PMT($B$4/$B$6,$B$5*$B$6,$B$3,,$C$12),"") -> 0 | D46: =IF(B46<=$B$5*$B$6,-IPMT($B$4/$B$6,B46,$B$5*$B$6,$B$3,,$C$12),"") -> 0 | E46: =IF(B46<=$B$5*$B$6,-PPMT($B$4/$B$6,B46,$B$5*$B$6,$B$3,,$C$12),"") -> 0 | F46: =IF(B46<=$B$5*$B$6,SUM($E$18:E46),"") -> 0 | G46: =IF(B46<=$B$5*$B$6,$B$3-F46,"") -> 0 | H46: =IF(G46="","",$C$11*G46) -> 0 | I46: =IF(H46="","",G46+H46) -> 0
B47: =IF(B46<$B$5*$B$6,B46+1,"") -> 30 | C47: =IF(B47<=$B$5*$B$6,-PMT($B$4/$B$6,$B$5*$B$6,$B$3,,$C$12),"") -> 0 | D47: =IF(B47<=$B$5*$B$6,-IPMT($B$4/$B$6,B47,$B$5*$B$6,$B$3,,$C$12),"") -> 0 | E47: =IF(B47<=$B$5*$B$6,-PPMT($B$4/$B$6,B47,$B$5*$B$6,$B$3,,$C$12),"") -> 0 | F47: =IF(B47<=$B$5*$B$6,SUM($E$18:E47),"") -> 0 | G47: =IF(B47<=$B$5*$B$6,$B$3-F47,"") -> 0 | H47: =IF(G47="","",$C$11*G47) -> 0 | I47: =IF(H47="","",G47+H47) -> 0
B48: =IF(B47<$B$5*$B$6,B47+1,"") -> 31 | C48: =IF(B48<=$B$5*$B$6,-PMT($B$4/$B$6,$B$5*$B$6,$B$3,,$C$12),"") -> 0 | D48: =IF(B48<=$B$5*$B$6,-IPMT($B$4/$B$6,B48,$B$5*$B$6,$B$3,,$C$12),"") -> 0 | E48: =IF(B48<=$B$5*$B$6,-PPMT($B$4/$B$6,B48,$B$5*$B$6,$B$3,,$C$12),"") -> 0 | F48: =IF(B48<=$B$5*$B$6,SUM($E$18:E48),"") -> 0 | G48: =IF(B48<=$B$5*$B$6,$B$3-F48,"") -> 0 | H48: =IF(G48="","",$C$11*G48) -> 0 | I48: =IF(H48="","",G48+H48) -> 0
B49: =IF(B48<$B$5*$B$6,B48+1,"") -> 32 | C49: =IF(B49<=$B$5*$B$6,-PMT($B$4/$B$6,$B$5*$B$6,$B$3,,$C$12),"") -> 0 | D49: =IF(B49<=$B$5*$B$6,-IPMT($B$4/$B$6,B49,$B$5*$B$6,$B$3,,$C$12),"") -> 0 | E49: =IF(B49<=$B$5*$B$6,-PPMT($B$4/$B$6,B49,$B$5*$B$6,$B$3,,$C$12),"") -> 0 | F49: =IF(B49<=$B$5*$B$6,SUM($E$18:E49),"") -> 0 | G49: =IF(B49<=$B$5*$B$6,$B$3-F49,"") -> 0 | H49: =IF(G49="","",$C$11*G49) -> 0 | I49: =IF(H49="","",G49+H49) -> 0
B50: =IF(B49<$B$5*$B$6,B49+1,"") -> 33 | C50: =IF(B50<=$B$5*$B$6,-PMT($B$4/$B$6,$B$5*$B$6,$B$3,,$C$12),"") -> 0 | D50: =IF(B50<=$B$5*$B$6,-IPMT($B$4/$B$6,B50,$B$5*$B$6,$B$3,,$C$12),"") -> 0 | E50: =IF(B50<=$B$5*$B$6,-PPMT($B$4/$B$6,B50,$B$5*$B$6,$B$3,,$C$12),"") -> 0 | F50: =IF(B50<=$B$5*$B$6,SUM($E$18:E50),"") -> 0 | G50: =IF(B50<=$B$5*$B$6,$B$3-F50,"") -> 0 | H50: =IF(G50="","",$C$11*G50) -> 0 | I50: =IF(H50="","",G50+H50) -> 0
B51: =IF(B50<$B$5*$B$6,B50+1,"") -> 34 | C51: =IF(B51<=$B$5*$B$6,-PMT($B$4/$B$6,$B$5*$B$6,$B$3,,$C$12),"") -> 0 | D51: =IF(B51<=$B$5*$B$6,-IPMT($B$4/$B$6,B51,$B$5*$B$6,$B$3,,$C$12),"") -> 0 | E51: =IF(B51<=$B$5*$B$6,-PPMT($B$4/$B$6,B51,$B$5*$B$6,$B$3,,$C$12),"") -> 0 | F51: =IF(B51<=$B$5*$B$6,SUM($E$18:E51),"") -> 0 | G51: =IF(B51<=$B$5*$B$6,$B$3-F51,"") -> 0 | H51: =IF(G51="","",$C$11*G51) -> 0 | I51: =IF(H51="","",G51+H51) -> 0
B52: =IF(B51<$B$5*$B$6,B51+1,"") -> 35 | C52: =IF(B52<=$B$5*$B$6,-PMT($B$4/$B$6,$B$5*$B$6,$B$3,,$C$12),"") -> 0 | D52: =IF(B52<=$B$5*$B$6,-IPMT($B$4/$B$6,B52,$B$5*$B$6,$B$3,,$C$12),"") -> 0 | E52: =IF(B52<=$B$5*$B$6,-PPMT($B$4/$B$6,B52,$B$5*$B$6,$B$3,,$C$12),"") -> 0 | F52: =IF(B52<=$B$5*$B$6,SUM($E$18:E52),"") -> 0 | G52: =IF(B52<=$B$5*$B$6,$B$3-F52,"") -> 0 | H52: =IF(G52="","",$C$11*G52) -> 0 | I52: =IF(H52="","",G52+H52) -> 0
B53: =IF(B52<$B$5*$B$6,B52+1,"") -> 36 | C53: =IF(B53<=$B$5*$B$6,-PMT($B$4/$B$6,$B$5*$B$6,$B$3,,$C$12),"") -> 0 | D53: =IF(B53<=$B$5*$B$6,-IPMT($B$4/$B$6,B53,$B$5*$B$6,$B$3,,$C$12),"") -> 0 | E53: =IF(B53<=$B$5*$B$6,-PPMT($B$4/$B$6,B53,$B$5*$B$6,$B$3,,$C$12),"") -> 0 | F53: =IF(B53<=$B$5*$B$6,SUM($E$18:E53),"") -> 0 | G53: =IF(B53<=$B$5*$B$6,$B$3-F53,"") -> 0 | H53: =IF(G53="","",$C$11*G53) -> 0 | I53: =IF(H53="","",G53+H53) -> 0
...
